<?xml version="1.0" ?>
<!-- =================================================================================== -->
<!-- |    This document was autogenerated by xacro from /opt/ros/noetic/share/franka_description/robots/panda_arm.urdf.xacro | -->
<!-- |    EDITING THIS FILE BY HAND IS NOT RECOMMENDED                                 | -->
<!-- =================================================================================== -->
<robot name="panda">
  <!-- =============================================================== -->
  <!-- || This file contains the robot without the hand and is used || -->
  <!-- || by franka_emulator::Model (which uses pinocchio). The file|| -->
  <!-- || does not contain official inertial properties of panda    || -->
  <!-- || robot. The original values came from the identification   || -->
  <!-- || results published in: Identification of the Franka Emika  || -->
  <!-- || PandaRobot With Retrieval of Feasible Parameters Using    || -->
  <!-- || Penalty-Based Optimization                                || -->
  <!-- || by: Claudio Gaz, Marco Cognetti, Alexander Oliva,         || -->
  <!-- || Paolo Robuffo Giordano, Alessandro de Lucaa               || -->
  <!-- || Current values were calculated by                         || -->
  <!-- || franka_emulator_inertia_calibrator, written by            || -->
  <!-- || Kyrylo Sovailo                                            || -->
  <!-- =============================================================== -->
  <link name="panda_link0">
    <visual>
      <origin rpy="0 0 0" xyz="0 0 0"/>
      <geometry>
        <mesh filename="visual/link0.dae"/>
      </geometry>
    </visual>
    <collision>
      <origin rpy="0 0 0" xyz="0 0 0"/>
      <geometry>
        <mesh filename="collision/link0.stl"/>
      </geometry>
    </collision>
    <inertial>
      <!-- Estimated guesses from CAD -->
      <origin rpy="0 0 0" xyz="-0.041018 -0.00014 0.049974"/>
      <mass value="0.629769"/>
      <inertia ixx="0.00315" ixy="8.2904E-07" ixz="0.00015" iyy="0.00388" iyz="8.2299E-06" izz="0.004285"/>
    </inertial>
  </link>
  <link name="panda_link1">
    <visual>
      <origin rpy="0 0 0" xyz="0 0 0"/>
      <geometry>
        <mesh filename="visual/link1.dae"/>
      </geometry>
    </visual>
    <collision>
      <origin rpy="0 0 0" xyz="0 0 0"/>
      <geometry>
        <mesh filename="collision/link1.stl"/>
      </geometry>
    </collision>
    <inertial>
      <origin rpy="0 0 0" xyz="0.0082121602797146209 -0.026532335711888823 -0.047138121275696603"/>
      <mass value="4.9706751871147938"/>
      <inertia ixx="0.70141461794089599" ixy="-0.00063981642154032682" ixz="0.0078364148804466946" iyy="0.70480134490761892" iyz="0.01074540620106503" izz="0.010111109106129931"/>
    </inertial>
  </link>
  <joint name="panda_joint1" type="revolute">
    <safety_controller k_position="100.0" k_velocity="40.0" soft_lower_limit="-2.8973" soft_upper_limit="2.8973"/>
    <origin rpy="0 0 0" xyz="0 0 0.333"/>
    <parent link="panda_link0"/>
    <child link="panda_link1"/>
    <axis xyz="0 0 1"/>
    <limit acceleration="15" effort="87" lower="-2.9671" upper="2.9671" velocity="2.5"/>
    <dynamics D="1" K="7000" damping="0.003" friction="0.0" mu_coulomb="0" mu_viscous="16"/>
  </joint>
  <link name="panda_link2">
    <visual>
      <origin rpy="0 0 0" xyz="0 0 0"/>
      <geometry>
        <mesh filename="visual/link2.dae"/>
      </geometry>
    </visual>
    <collision>
      <origin rpy="0 0 0" xyz="0 0 0"/>
      <geometry>
        <mesh filename="collision/link2.stl"/>
      </geometry>
    </collision>
    <inertial>
      <origin rpy="0 0 0" xyz="-0.0088444802449167883 -0.027531520310653038 -0.00055850347148591131"/>
      <mass value="0.64712411452542207"/>
      <inertia ixx="0.012028228395010528" ixy="-0.005176957021186453" ixz="0.028416723889140006" iyy="0.034001000715476563" iyz="-0.0034872992153212263" izz="0.026005490424668338"/>
    </inertial>
  </link>
  <joint name="panda_joint2" type="revolute">
    <safety_controller k_position="100.0" k_velocity="40.0" soft_lower_limit="-1.7628" soft_upper_limit="1.7628"/>
    <origin rpy="-1.5707963267948966 0 0" xyz="0 0 0"/>
    <parent link="panda_link1"/>
    <child link="panda_link2"/>
    <axis xyz="0 0 1"/>
    <limit acceleration="7.5" effort="87" lower="-1.8326" upper="1.8326" velocity="2.5"/>
    <dynamics D="1" K="7000" damping="0.003" friction="0.0" mu_coulomb="0" mu_viscous="16"/>
  </joint>
  <link name="panda_link3">
    <visual>
      <origin rpy="0 0 0" xyz="0 0 0"/>
      <geometry>
        <mesh filename="visual/link3.dae"/>
      </geometry>
    </visual>
    <collision>
      <origin rpy="0 0 0" xyz="0 0 0"/>
      <geometry>
        <mesh filename="collision/link3.stl"/>
      </geometry>
    </collision>
    <inertial>
      <origin rpy="0 0 0" xyz="0.028340188017725303 0.037617533422114727 -0.067208806995820797"/>
      <mass value="3.2283417206016849"/>
      <inertia ixx="0.035865608781665073" ixy="-0.0048981742215283711" ixz="-0.01683647440270046" iyy="0.041062395573147469" iyz="-0.012957871374295925" izz="0.0072954180594979098"/>
    </inertial>
  </link>
  <joint name="panda_joint3" type="revolute">
    <safety_controller k_position="100.0" k_velocity="40.0" soft_lower_limit="-2.8973" soft_upper_limit="2.8973"/>
    <origin rpy="1.5707963267948966 0 0" xyz="0 -0.316 0"/>
    <parent link="panda_link2"/>
    <child link="panda_link3"/>
    <axis xyz="0 0 1"/>
    <limit acceleration="12.5" effort="87" lower="-2.9671" upper="2.9671" velocity="2.5"/>
    <dynamics D="1" K="7000" damping="0.003" friction="0.0" mu_coulomb="0" mu_viscous="16"/>
  </joint>
  <link name="panda_link4">
    <visual>
      <origin rpy="0 0 0" xyz="0 0 0"/>
      <geometry>
        <mesh filename="visual/link4.dae"/>
      </geometry>
    </visual>
    <collision>
      <origin rpy="0 0 0" xyz="0 0 0"/>
      <geometry>
        <mesh filename="collision/link4.stl"/>
      </geometry>
    </collision>
    <inertial>
      <origin rpy="0 0 0" xyz="-0.052863658713578371 0.10286796966271235 0.027230575794129856"/>
      <mass value="3.5877058164189872"/>
      <inertia ixx="0.023713305935381724" ixy="0.019494904018681623" ixz="-0.00041806758858047981" iyy="0.016777579582937466" iyz="0.0073688153189040975" izz="0.03323445513208665"/>
    </inertial>
  </link>
  <joint name="panda_joint4" type="revolute">
    <safety_controller k_position="100.0" k_velocity="40.0" soft_lower_limit="-3.0718" soft_upper_limit="-0.0698"/>
    <origin rpy="1.5707963267948966 0 0" xyz="0.0825 0 0"/>
    <parent link="panda_link3"/>
    <child link="panda_link4"/>
    <axis xyz="0 0 1"/>
    <limit acceleration="12.5" effort="87" lower="-3.1416" upper="-0.4" velocity="2.5"/>
    <dynamics D="1" K="7000" damping="0.003" friction="0.0" mu_coulomb="0" mu_viscous="16"/>
  </joint>
  <link name="panda_link5">
    <visual>
      <origin rpy="0 0 0" xyz="0 0 0"/>
      <geometry>
        <mesh filename="visual/link5.dae"/>
      </geometry>
    </visual>
    <collision>
      <origin rpy="0 0 0" xyz="0 0 0"/>
      <geometry>
        <mesh filename="collision/link5.stl"/>
      </geometry>
    </collision>
    <inertial>
      <origin rpy="0 0 0" xyz="-0.0081910657546574537 0.042932437976240877 -0.03621309770351528"/>
      <mass value="1.2258764841419181"/>
      <inertia ixx="0.039833353765046244" ixy="-0.0041636653470603583" ixz="-0.0057791872240629304" iyy="0.027963868212344253" iyz="0.0057981330723796617" izz="0.0058527143406942126"/>
    </inertial>
  </link>
  <joint name="panda_joint5" type="revolute">
    <safety_controller k_position="100.0" k_velocity="40.0" soft_lower_limit="-2.8973" soft_upper_limit="2.8973"/>
    <origin rpy="-1.5707963267948966 0 0" xyz="-0.0825 0.384 0"/>
    <parent link="panda_link4"/>
    <child link="panda_link5"/>
    <axis xyz="0 0 1"/>
    <limit acceleration="15" effort="12" lower="-2.9671" upper="2.9671" velocity="3"/>
    <dynamics D="1" K="7000" damping="0.003" friction="0.0" mu_coulomb="0" mu_viscous="16"/>
  </joint>
  <link name="panda_link6">
    <visual>
      <origin rpy="0 0 0" xyz="0 0 0"/>
      <geometry>
        <mesh filename="visual/link6.dae"/>
      </geometry>
    </visual>
    <collision>
      <origin rpy="0 0 0" xyz="0 0 0"/>
      <geometry>
        <mesh filename="collision/link6.stl"/>
      </geometry>
    </collision>
    <inertial>
      <origin rpy="0 0 0" xyz="0.060550072294159214 -0.013508438365027796 -0.014648696562393272"/>
      <mass value="1.6660195957719575"/>
      <inertia ixx="0.0018946535529745841" ixy="3.0085693236067733e-05" ixz="-0.0014917301754574759" iyy="0.0059333708668997337" iyz="0.001150006504840946" izz="0.0039230158812056833"/>
    </inertial>
  </link>
  <joint name="panda_joint6" type="revolute">
    <safety_controller k_position="100.0" k_velocity="40.0" soft_lower_limit="-0.0175" soft_upper_limit="3.7525"/>
    <origin rpy="1.5707963267948966 0 0" xyz="0 0 0"/>
    <parent link="panda_link5"/>
    <child link="panda_link6"/>
    <axis xyz="0 0 1"/>
    <limit acceleration="20" effort="12" lower="-0.0873" upper="3.8223" velocity="3"/>
    <dynamics D="1" K="7000" damping="0.003" friction="0.0" mu_coulomb="0" mu_viscous="16"/>
  </joint>
  <link name="panda_link7">
    <visual>
      <origin rpy="0 0 0" xyz="0 0 0"/>
      <geometry>
        <mesh filename="visual/link7.dae"/>
      </geometry>
    </visual>
    <collision>
      <origin rpy="0 0 0" xyz="0 0 0"/>
      <geometry>
        <mesh filename="collision/link7.stl"/>
      </geometry>
    </collision>
    <inertial>
      <origin rpy="0 0 0" xyz="0.0084850731223620312 -0.00063346827849231481 0.061428526086978817"/>
      <mass value="0.73598318978014388"/>
      <inertia ixx="0.0096273165930081117" ixy="0.0011836273982315374" ixz="0.0021412918431209403" iyy="0.011335955410605407" iyz="-0.000625294249958001" izz="0.0063944769299665851"/>
    </inertial>
  </link>
  <joint name="panda_joint7" type="revolute">
    <safety_controller k_position="100.0" k_velocity="40.0" soft_lower_limit="-2.8973" soft_upper_limit="2.8973"/>
    <origin rpy="1.5707963267948966 0 0" xyz="0.088 0 0"/>
    <parent link="panda_link6"/>
    <child link="panda_link7"/>
    <axis xyz="0 0 1"/>
    <limit acceleration="20" effort="12" lower="-2.9671" upper="2.9671" velocity="3"/>
    <dynamics D="1" K="7000" damping="0.003" friction="0.0" mu_coulomb="0" mu_viscous="16"/>
  </joint>
  <link name="panda_link8"/>
  <joint name="panda_joint8" type="fixed">
    <origin rpy="0 0 0" xyz="0 0 0.107"/>
    <parent link="panda_link7"/>
    <child link="panda_link8"/>
    <axis xyz="0 0 0"/>
  </joint>
  <!-- Gazebo requires a joint to a link called "world" for statically mounted robots -->
  <link name="world"/>
  <joint name="world_joint" type="fixed">
    <origin rpy="0 0 0" xyz="0 0 0"/>
    <parent link="world"/>
    <child link="panda_link0"/>
  </joint>
  <gazebo reference="panda_joint1">
    <!-- Needed for ODE to output external wrenches on joints -->
    <provideFeedback>true</provideFeedback>
  </gazebo>
  <transmission name="panda_joint1_transmission">
    <type>transmission_interface/SimpleTransmission</type>
    <joint name="panda_joint1">
      <hardwareInterface>hardware_interface/EffortJointInterface</hardwareInterface>
    </joint>
    <actuator name="panda_joint1_motor">
      <hardwareInterface>hardware_interface/EffortJointInterface</hardwareInterface>
    </actuator>
  </transmission>
  <gazebo reference="panda_joint2">
    <!-- Needed for ODE to output external wrenches on joints -->
    <provideFeedback>true</provideFeedback>
  </gazebo>
  <transmission name="panda_joint2_transmission">
    <type>transmission_interface/SimpleTransmission</type>
    <joint name="panda_joint2">
      <hardwareInterface>hardware_interface/EffortJointInterface</hardwareInterface>
    </joint>
    <actuator name="panda_joint2_motor">
      <hardwareInterface>hardware_interface/EffortJointInterface</hardwareInterface>
    </actuator>
  </transmission>
  <gazebo reference="panda_joint3">
    <!-- Needed for ODE to output external wrenches on joints -->
    <provideFeedback>true</provideFeedback>
  </gazebo>
  <transmission name="panda_joint3_transmission">
    <type>transmission_interface/SimpleTransmission</type>
    <joint name="panda_joint3">
      <hardwareInterface>hardware_interface/EffortJointInterface</hardwareInterface>
    </joint>
    <actuator name="panda_joint3_motor">
      <hardwareInterface>hardware_interface/EffortJointInterface</hardwareInterface>
    </actuator>
  </transmission>
  <gazebo reference="panda_joint4">
    <!-- Needed for ODE to output external wrenches on joints -->
    <provideFeedback>true</provideFeedback>
  </gazebo>
  <transmission name="panda_joint4_transmission">
    <type>transmission_interface/SimpleTransmission</type>
    <joint name="panda_joint4">
      <hardwareInterface>hardware_interface/EffortJointInterface</hardwareInterface>
    </joint>
    <actuator name="panda_joint4_motor">
      <hardwareInterface>hardware_interface/EffortJointInterface</hardwareInterface>
    </actuator>
  </transmission>
  <gazebo reference="panda_joint5">
    <!-- Needed for ODE to output external wrenches on joints -->
    <provideFeedback>true</provideFeedback>
  </gazebo>
  <transmission name="panda_joint5_transmission">
    <type>transmission_interface/SimpleTransmission</type>
    <joint name="panda_joint5">
      <hardwareInterface>hardware_interface/EffortJointInterface</hardwareInterface>
    </joint>
    <actuator name="panda_joint5_motor">
      <hardwareInterface>hardware_interface/EffortJointInterface</hardwareInterface>
    </actuator>
  </transmission>
  <gazebo reference="panda_joint6">
    <!-- Needed for ODE to output external wrenches on joints -->
    <provideFeedback>true</provideFeedback>
  </gazebo>
  <transmission name="panda_joint6_transmission">
    <type>transmission_interface/SimpleTransmission</type>
    <joint name="panda_joint6">
      <hardwareInterface>hardware_interface/EffortJointInterface</hardwareInterface>
    </joint>
    <actuator name="panda_joint6_motor">
      <hardwareInterface>hardware_interface/EffortJointInterface</hardwareInterface>
    </actuator>
  </transmission>
  <gazebo reference="panda_joint7">
    <!-- Needed for ODE to output external wrenches on joints -->
    <provideFeedback>true</provideFeedback>
  </gazebo>
  <transmission name="panda_joint7_transmission">
    <type>transmission_interface/SimpleTransmission</type>
    <joint name="panda_joint7">
      <hardwareInterface>hardware_interface/EffortJointInterface</hardwareInterface>
    </joint>
    <actuator name="panda_joint7_motor">
      <hardwareInterface>hardware_interface/EffortJointInterface</hardwareInterface>
    </actuator>
  </transmission>
  <transmission name="panda_franka_state">
    <type>franka_hw/FrankaStateInterface</type>
    <joint name="panda_joint1">
      <hardwareInterface>franka_hw/FrankaStateInterface</hardwareInterface>
    </joint>
    <joint name="panda_joint2">
      <hardwareInterface>franka_hw/FrankaStateInterface</hardwareInterface>
    </joint>
    <joint name="panda_joint3">
      <hardwareInterface>franka_hw/FrankaStateInterface</hardwareInterface>
    </joint>
    <joint name="panda_joint4">
      <hardwareInterface>franka_hw/FrankaStateInterface</hardwareInterface>
    </joint>
    <joint name="panda_joint5">
      <hardwareInterface>franka_hw/FrankaStateInterface</hardwareInterface>
    </joint>
    <joint name="panda_joint6">
      <hardwareInterface>franka_hw/FrankaStateInterface</hardwareInterface>
    </joint>
    <joint name="panda_joint7">
      <hardwareInterface>franka_hw/FrankaStateInterface</hardwareInterface>
    </joint>
    <actuator name="panda_motor1">
      <hardwareInterface>franka_hw/FrankaStateInterface</hardwareInterface>
    </actuator>
    <actuator name="panda_motor2">
      <hardwareInterface>franka_hw/FrankaStateInterface</hardwareInterface>
    </actuator>
    <actuator name="panda_motor3">
      <hardwareInterface>franka_hw/FrankaStateInterface</hardwareInterface>
    </actuator>
    <actuator name="panda_motor4">
      <hardwareInterface>franka_hw/FrankaStateInterface</hardwareInterface>
    </actuator>
    <actuator name="panda_motor5">
      <hardwareInterface>franka_hw/FrankaStateInterface</hardwareInterface>
    </actuator>
    <actuator name="panda_motor6">
      <hardwareInterface>franka_hw/FrankaStateInterface</hardwareInterface>
    </actuator>
    <actuator name="panda_motor7">
      <hardwareInterface>franka_hw/FrankaStateInterface</hardwareInterface>
    </actuator>
  </transmission>
  <transmission name="panda_franka_model">
    <type>franka_hw/FrankaModelInterface</type>
    <joint name="panda_joint1">
      <role>root</role>
      <hardwareInterface>franka_hw/FrankaModelInterface</hardwareInterface>
    </joint>
    <joint name="panda_joint8">
      <role>tip</role>
      <hardwareInterface>franka_hw/FrankaModelInterface</hardwareInterface>
    </joint>
    <actuator name="panda_joint1_motor_root">
      <hardwareInterface>franka_hw/FrankaModelInterface</hardwareInterface>
    </actuator>
    <actuator name="panda_joint8_motor_tip">
      <hardwareInterface>franka_hw/FrankaModelInterface</hardwareInterface>
    </actuator>
  </transmission>
  <gazebo>
    <self_collide>true</self_collide>
  </gazebo>
</robot>

